ERROR:__main__:got an error
Traceback (most recent call last):
  File "/home/bsasank/python_prgrms/logger_prac.py", line 9, in division
    result = a/b
ZeroDivisionError: division by zero
